INFO: Running heudiconv version 0.11.3+d20220512 latest 0.11.4
INFO: Need to process 1 study sessions
INFO: Initiating Dataset(/out)
INFO: Clear progress bars
INFO: Refresh progress bars
INFO: Total: starting
INFO: 
INFO: Clear progress bars
INFO: Refresh progress bars
INFO: Total: processed result for /out
INFO: Clear progress bars
INFO: Refresh progress bars
INFO: Total: done
INFO: Clear progress bars
INFO: Refresh progress bars
INFO: Total: starting
INFO: 
INFO: Clear progress bars
INFO: Refresh progress bars
[WARNING] Received an exception CommandError(CommandError: 'git -c diff.ignoreSubmodules=none -c annex.largefiles=nothing add --verbose -- /out/.gitmodules' failed with exitcode 128 [err: 'fatal: Unable to create '/out/.git/index.lock': File exists.

Another git process seems to be running in this repository, e.g.
an editor opened by 'git commit'. Please make sure all processes
are terminated then try again. If it still fails, a git process
may have crashed in this repository earlier:
remove the file manually to continue.']). Canceling not-yet running jobs and waiting for completion of running. You can force earlier forceful exit by Ctrl-C. 
WARNING: Received an exception CommandError(CommandError: 'git -c diff.ignoreSubmodules=none -c annex.largefiles=nothing add --verbose -- /out/.gitmodules' failed with exitcode 128 [err: 'fatal: Unable to create '/out/.git/index.lock': File exists.

Another git process seems to be running in this repository, e.g.
an editor opened by 'git commit'. Please make sure all processes
are terminated then try again. If it still fails, a git process
may have crashed in this repository earlier:
remove the file manually to continue.']). Canceling not-yet running jobs and waiting for completion of running. You can force earlier forceful exit by Ctrl-C.
[INFO] Canceled 0 out of 0 jobs. 0 left running. 
INFO: Canceled 0 out of 0 jobs. 0 left running.
Traceback (most recent call last):
  File "/opt/miniconda-latest/lib/python3.7/site-packages/datalad/support/parallel.py", line 368, in _iter_threads
    raise _FinalShutdown()
datalad.support.parallel._FinalShutdown

During handling of the above exception, another exception occurred:

Traceback (most recent call last):
  File "/opt/miniconda-latest/bin/heudiconv", line 33, in <module>
    sys.exit(load_entry_point('heudiconv', 'console_scripts', 'heudiconv')())
  File "/src/heudiconv/heudiconv/cli/run.py", line 24, in main
    workflow(**kwargs)
  File "/src/heudiconv/heudiconv/main.py", line 374, in workflow
    bids_options)
  File "/src/heudiconv/heudiconv/external/dlad.py", line 30, in prepare_datalad
    bids=bids)
  File "/src/heudiconv/heudiconv/external/dlad.py", line 114, in add_to_datalad
    force=True,
  File "/opt/miniconda-latest/lib/python3.7/site-packages/datalad/distribution/dataset.py", line 502, in apply_func
    return f(*args, **kwargs)
  File "/opt/miniconda-latest/lib/python3.7/site-packages/datalad/interface/utils.py", line 447, in eval_func
    return return_func(*args, **kwargs)
  File "/opt/miniconda-latest/lib/python3.7/site-packages/datalad/interface/utils.py", line 439, in return_func
    results = list(results)
  File "/opt/miniconda-latest/lib/python3.7/site-packages/datalad/interface/utils.py", line 369, in generator_func
    allkwargs):
  File "/opt/miniconda-latest/lib/python3.7/site-packages/datalad/interface/utils.py", line 544, in _process_results
    for res in results:
  File "/opt/miniconda-latest/lib/python3.7/site-packages/datalad/core/local/create.py", line 451, in __call__
    result_renderer='disabled',
  File "/opt/miniconda-latest/lib/python3.7/site-packages/datalad/interface/utils.py", line 369, in generator_func
    allkwargs):
  File "/opt/miniconda-latest/lib/python3.7/site-packages/datalad/interface/utils.py", line 544, in _process_results
    for res in results:
  File "/opt/miniconda-latest/lib/python3.7/site-packages/datalad/core/local/save.py", line 398, in __call__
    lgr=lgr,
  File "/opt/miniconda-latest/lib/python3.7/site-packages/datalad/support/parallel.py", line 535, in __iter__
    for res in super().__iter__():
  File "/opt/miniconda-latest/lib/python3.7/site-packages/datalad/support/parallel.py", line 265, in __iter__
    yield from self._iter_threads(self._jobs)
  File "/opt/miniconda-latest/lib/python3.7/site-packages/datalad/support/parallel.py", line 417, in _iter_threads
    self.shutdown(force=True, exception=self._producer_exception or interrupted_by_exception)
  File "/opt/miniconda-latest/lib/python3.7/site-packages/datalad/support/parallel.py", line 233, in shutdown
    raise exception
  File "/opt/miniconda-latest/lib/python3.7/site-packages/datalad/support/parallel.py", line 401, in _iter_threads
    done_useful |= self._pop_done_futures(lgr)
  File "/opt/miniconda-latest/lib/python3.7/site-packages/datalad/support/parallel.py", line 463, in _pop_done_futures
    raise exception
  File "/opt/miniconda-latest/lib/python3.7/concurrent/futures/thread.py", line 57, in run
    result = self.fn(*self.args, **self.kwargs)
  File "/opt/miniconda-latest/lib/python3.7/site-packages/datalad/support/parallel.py", line 329, in consumer_worker
    for r in res:
  File "/opt/miniconda-latest/lib/python3.7/site-packages/datalad/core/local/save.py", line 322, in save_ds
    amend=amend):
  File "/opt/miniconda-latest/lib/python3.7/site-packages/datalad/support/gitrepo.py", line 3447, in save_
    {op.join(self.path, '.gitmodules'): None}):
  File "/opt/miniconda-latest/lib/python3.7/site-packages/datalad/support/gitrepo.py", line 3579, in _save_add
    files=list(files.keys()),
  File "/opt/miniconda-latest/lib/python3.7/site-packages/datalad/dataset/gitrepo.py", line 388, in _call_git
    env=env):
  File "/opt/miniconda-latest/lib/python3.7/site-packages/datalad/dataset/gitrepo.py", line 345, in _generator_call_git
    for file_no, content in generator:
  File "/opt/miniconda-latest/lib/python3.7/site-packages/datalad/runner/gitrunner.py", line 268, in run_on_filelist_chunks_items_
    yield from chunk_generator
  File "/opt/miniconda-latest/lib/python3.7/_collections_abc.py", line 317, in __next__
    return self.send(None)
  File "/opt/miniconda-latest/lib/python3.7/site-packages/datalad/runner/nonasyncrunner.py", line 98, in send
    self._check_result()
  File "/opt/miniconda-latest/lib/python3.7/site-packages/datalad/runner/nonasyncrunner.py", line 80, in _check_result
    self.runner._check_result()
  File "/opt/miniconda-latest/lib/python3.7/site-packages/datalad/runner/nonasyncrunner.py", line 259, in _check_result
    stderr=decoded_output.get("stderr", None))
datalad.runner.exception.CommandError: CommandError: 'git -c diff.ignoreSubmodules=none -c annex.largefiles=nothing add --verbose -- /out/.gitmodules' failed with exitcode 128 [err: 'fatal: Unable to create '/out/.git/index.lock': File exists.

Another git process seems to be running in this repository, e.g.
an editor opened by 'git commit'. Please make sure all processes
are terminated then try again. If it still fails, a git process
may have crashed in this repository earlier:
remove the file manually to continue.']
